Workbook

Sheet Data
A1: Icono part.abiertas/comp. | B1: Asignación | C1: Nº documento | D1: División | E1: Clase de documento | F1: Fecha de documento | G1: Clave contabiliz. | H1: Importe en moneda local | I1: Moneda local | J1: Indicador impuestos | K1: Doc.compensación | L1: Nombre | M1: Fe.contabilización | N1: Documento compras | O1: Posición | P1: CONCATENA | Q1: Fecha de entrega | R1: Grupo de compras | S1: Proveedor/Centro suministrador | T1: OPERADOR OC
C2: 1900000618 | E2: GR | F2: 46283 | G2: 86 | H2: 402804.5 | I2: ARS | J2: C1 | L2: HELING S.A. | M2: 46283 | N2: 4500127116 | O2: 10 | P2: =_xlfn.CONCAT(N2:O2) -> 450012711610 | Q2: {=VLOOKUP(P2,Hoja1!C:F,{2,3,4},FALSE)} -> 46210 | R2: CGT | S2: 1000001583 HELING S.A. | T2: =VLOOKUP(P2,Hoja2!C:D,2,FALSE) -> WVENTURINI
C3: 1900000618 | E3: GR | F3: 46283 | G3: 86 | H3: 50094 | I3: ARS | J3: C1 | L3: HELING S.A. | M3: 46283 | N3: 4500114743 | O3: 320 | P3: =_xlfn.CONCAT(N3:O3) -> 4500114743320 | Q3: {=VLOOKUP(P3,Hoja1!C:F,{2,3,4},FALSE)} -> 46290 | R3: CGT | S3: 1000001583 HELING S.A. | T3: =VLOOKUP(P3,Hoja2!C:D,2,FALSE) -> EFUNES
C4: 1900000618 | E4: GR | F4: 46283 | G4: 86 | H4: 181130 | I4: ARS | J4: C1 | L4: HELING S.A. | M4: 46283 | N4: 4500114743 | O4: 330 | P4: =_xlfn.CONCAT(N4:O4) -> 4500114743330 | Q4: {=VLOOKUP(P4,Hoja1!C:F,{2,3,4},FALSE)} -> 46301 | R4: CGT | S4: 1000001583 HELING S.A. | T4: =VLOOKUP(P4,Hoja2!C:D,2,FALSE) -> EFUNES
C5: 5100000267 | E5: RE | F5: 46029 | G5: 86 | H5: 140530 | I5: ARS | J5: C1 | L5: HELING S.A. | M5: 46029 | N5: 4500114743 | O5: 10 | P5: =_xlfn.CONCAT(N5:O5) -> 450011474310 | Q5: {=VLOOKUP(P5,Hoja1!C:F,{2,3,4},FALSE)} -> 46290 | R5: CGT | S5: 1000001583 HELING S.A. | T5: =VLOOKUP(P5,Hoja2!C:D,2,FALSE) -> EFUNES
C6: 5100000296 | E6: RE | F6: 46037 | G6: 86 | H6: 4388722 | I6: ARS | J6: C1 | L6: HELING S.A. | M6: 46038 | N6: 4500114743 | O6: 40 | P6: =_xlfn.CONCAT(N6:O6) -> 450011474340 | Q6: {=VLOOKUP(P6,Hoja1!C:F,{2,3,4},FALSE)} -> 46290 | R6: CGT | S6: 1000001583 HELING S.A. | T6: =VLOOKUP(P6,Hoja2!C:D,2,FALSE) -> EFUNES
C7: 5100000296 | E7: RE | F7: 46037 | G7: 86 | H7: 1314105 | I7: ARS | J7: C1 | L7: HELING S.A. | M7: 46038 | N7: 4500114743 | O7: 270 | P7: =_xlfn.CONCAT(N7:O7) -> 4500114743270 | Q7: {=VLOOKUP(P7,Hoja1!C:F,{2,3,4},FALSE)} -> 46290 | R7: CGT | S7: 1000001583 HELING S.A. | T7: =VLOOKUP(P7,Hoja2!C:D,2,FALSE) -> EFUNES
C8: 5100000400 | E8: RE | F8: 46057 | G8: 86 | H8: 245000 | I8: ARS | J8: C1 | L8: ANTONIO B ATENOR E HIJOS S R L | M8: 46062 | N8: 4500117831 | O8: 10 | P8: =_xlfn.CONCAT(N8:O8) -> 450011783110 | Q8: {=VLOOKUP(P8,Hoja1!C:F,{2,3,4},FALSE)} -> 46056 | R8: C27 | S8: 1000007611 ANTONIO B ATENOR E HIJOS S R L | T8: =VLOOKUP(P8,Hoja2!C:D,2,FALSE) -> JESPARZA
C9: 5100000461 | E9: RE | F9: 46083 | G9: 86 | H9: 4104100 | I9: ARS | J9: C1 | L9: HELING S.A. | M9: 46083 | N9: 4500114743 | O9: 40 | P9: =_xlfn.CONCAT(N9:O9) -> 450011474340 | Q9: {=VLOOKUP(P9,Hoja1!C:F,{2,3,4},FALSE)} -> 46290 | R9: CGT | S9: 1000001583 HELING S.A. | T9: =VLOOKUP(P9,Hoja2!C:D,2,FALSE) -> EFUNES
C10: 5100000461 | E10: RE | F10: 46083 | G10: 86 | H10: 3693690 | I10: ARS | J10: C1 | L10: HELING S.A. | M10: 46083 | N10: 4500114743 | O10: 50 | P10: =_xlfn.CONCAT(N10:O10) -> 450011474350 | Q10: {=VLOOKUP(P10,Hoja1!C:F,{2,3,4},FALSE)} -> 46290 | R10: CGT | S10: 1000001583 HELING S.A. | T10: =VLOOKUP(P10,Hoja2!C:D,2,FALSE) -> EFUNES
C11: 5100000461 | E11: RE | F11: 46083 | G11: 86 | H11: 783640 | I11: ARS | J11: C1 | L11: HELING S.A. | M11: 46083 | N11: 4500114743 | O11: 30 | P11: =_xlfn.CONCAT(N11:O11) -> 450011474330 | Q11: {=VLOOKUP(P11,Hoja1!C:F,{2,3,4},FALSE)} -> 46290 | R11: CGT | S11: 1000001583 HELING S.A. | T11: =VLOOKUP(P11,Hoja2!C:D,2,FALSE) -> EFUNES
C12: 5100000461 | E12: RE | F12: 46083 | G12: 86 | H12: 1430 | I12: ARS | J12: C1 | L12: HELING S.A. | M12: 46083 | N12: 4500114743 | O12: 170 | P12: =_xlfn.CONCAT(N12:O12) -> 4500114743170 | Q12: {=VLOOKUP(P12,Hoja1!C:F,{2,3,4},FALSE)} -> 46290 | R12: CGT | S12: 1000001583 HELING S.A. | T12: =VLOOKUP(P12,Hoja2!C:D,2,FALSE) -> EFUNES
C13: 5100000461 | E13: RE | F13: 46083 | G13: 86 | H13: 42900 | I13: ARS | J13: C1 | L13: HELING S.A. | M13: 46083 | N13: 4500114743 | O13: 480 | P13: =_xlfn.CONCAT(N13:O13) -> 4500114743480 | Q13: {=VLOOKUP(P13,Hoja1!C:F,{2,3,4},FALSE)} -> 46290 | R13: CGT | S13: 1000001583 HELING S.A. | T13: =VLOOKUP(P13,Hoja2!C:D,2,FALSE) -> EFUNES
C14: 5100000461 | E14: RE | F14: 46083 | G14: 86 | H14: 1430 | I14: ARS | J14: C1 | L14: HELING S.A. | M14: 46083 | N14: 4500114743 | O14: 320 | P14: =_xlfn.CONCAT(N14:O14) -> 4500114743320 | Q14: {=VLOOKUP(P14,Hoja1!C:F,{2,3,4},FALSE)} -> 46290 | R14: CGT | S14: 1000001583 HELING S.A. | T14: =VLOOKUP(P14,Hoja2!C:D,2,FALSE) -> EFUNES
C15: 5100000636 | D15: 7000 | E15: RE | F15: 46038 | G15: 86 | H15: 85148.23 | I15: ARS | J15: C1 | L15: JACARANDA S.A. | M15: 46118 | N15: 4500109514 | O15: 10 | P15: =_xlfn.CONCAT(N15:O15) -> 450010951410 | Q15: {=VLOOKUP(P15,Hoja1!C:F,{2,3,4},FALSE)} -> 46162 | R15: C01 | S15: 1000008967 JACARANDA S.A. | T15: =VLOOKUP(P15,Hoja2!C:D,2,FALSE) -> MMOHR
C16: 5100000828 | E16: RE | F16: 46153 | G16: 86 | H16: 815080 | I16: ARS | J16: C1 | L16: HELING S.A. | M16: 46153 | N16: 4500127295 | O16: 20 | P16: =_xlfn.CONCAT(N16:O16) -> 450012729520 | Q16: {=VLOOKUP(P16,Hoja1!C:F,{2,3,4},FALSE)} -> 46301 | R16: CGT | S16: 1000001583 HELING S.A. | T16: =VLOOKUP(P16,Hoja2!C:D,2,FALSE) -> WVENTURINI
C17: 5100001133 | D17: 7000 | E17: RE | F17: 46149 | G17: 96 | H17: -350000 | I17: ARS | J17: C1 | L17: MARADONA PRADO ISABEL MARGARIT | M17: 46184 | N17: 4500126954 | O17: 10 | P17: =_xlfn.CONCAT(N17:O17) -> 450012695410 | Q17: {=VLOOKUP(P17,Hoja1!C:F,{2,3,4},FALSE)} -> 46169 | R17: C01 | S17: 1000001560 MARADONA PRADO ISABEL MARGARIT | T17: =VLOOKUP(P17,Hoja2!C:D,2,FALSE) -> AZAPANA
C18: 5100001133 | D18: 7000 | E18: RE | F18: 46149 | G18: 96 | H18: -560000 | I18: ARS | J18: C1 | L18: MARADONA PRADO ISABEL MARGARIT | M18: 46184 | N18: 4500126954 | O18: 20 | P18: =_xlfn.CONCAT(N18:O18) -> 450012695420 | Q18: {=VLOOKUP(P18,Hoja1!C:F,{2,3,4},FALSE)} -> 46169 | R18: C01 | S18: 1000001560 MARADONA PRADO ISABEL MARGARIT | T18: =VLOOKUP(P18,Hoja2!C:D,2,FALSE) -> AZAPANA
C19: 5100001148 | D19: 7000 | E19: RE | F19: 46205 | G19: 86 | H19: 411800 | I19: ARS | J19: C2 | L19: PRODUCTOS SERVICIOS Y DISTRIBUCIONE | M19: 46209 | N19: 4500123262 | O19: 10 | P19: =_xlfn.CONCAT(N19:O19) -> 450012326210 | Q19: {=VLOOKUP(P19,Hoja1!C:F,{2,3,4},FALSE)} -> 46233 | R19: C25 | S19: 1000012132 PRODUCTOS SERVICIOS Y DISTRIBUCIONE | T19: =VLOOKUP(P19,Hoja2!C:D,2,FALSE) -> MPITTIA
C20: 5100001289 | D20: 7000 | E20: RE | F20: 46219 | G20: 86 | H20: 118860 | I20: ARS | J20: C1 | L20: JACARANDA S.A. | M20: 46232 | N20: 4500123036 | O20: 10 | P20: =_xlfn.CONCAT(N20:O20) -> 450012303610 | Q20: {=VLOOKUP(P20,Hoja1!C:F,{2,3,4},FALSE)} -> 46282 | R20: C01 | S20: 1000008967 JACARANDA S.A. | T20: =VLOOKUP(P20,Hoja2!C:D,2,FALSE) -> GLUNA
C21: 5100001479 | D21: 7000 | E21: RE | F21: 46266 | G21: 86 | H21: 1582519.7 | I21: ARS | J21: C2 | L21: TRANSPORTE TMS S. A. S. | M21: 46273 | N21: 4500137227 | O21: 10 | P21: =_xlfn.CONCAT(N21:O21) -> 450013722710 | Q21: {=VLOOKUP(P21,Hoja1!C:F,{2,3,4},FALSE)} -> 46325 | R21: C25 | S21: 1000012097 TRANSPORTE TMS S. A. S. | T21: =VLOOKUP(P21,Hoja2!C:D,2,FALSE) -> MPITTIA
C22: 5100001520 | D22: 7000 | E22: RE | F22: 46265 | G22: 86 | H22: 19810 | I22: ARS | J22: C1 | L22: JACARANDA S.A. | M22: 46286 | N22: 4500123036 | O22: 10 | P22: =_xlfn.CONCAT(N22:O22) -> 450012303610 | Q22: {=VLOOKUP(P22,Hoja1!C:F,{2,3,4},FALSE)} -> 46282 | R22: C01 | S22: 1000008967 JACARANDA S.A. | T22: =VLOOKUP(P22,Hoja2!C:D,2,FALSE) -> GLUNA
C23: 5100001614 | E23: RE | F23: 46275 | G23: 96 | H23: -126446.84 | I23: ARS | J23: C1 | L23: SALLAGO FEDERICO MIGUEL | M23: 46287 | N23: 4500138923 | O23: 10 | P23: =_xlfn.CONCAT(N23:O23) -> 450013892310 | Q23: {=VLOOKUP(P23,Hoja1!C:F,{2,3,4},FALSE)} -> 46303 | R23: C01 | S23: 1000011519 SALLAGO FEDERICO MIGUEL | T23: =VLOOKUP(P23,Hoja2!C:D,2,FALSE) -> AZAPANA
C24: 5100001614 | E24: RE | F24: 46275 | G24: 96 | H24: -126446.84 | I24: ARS | J24: C1 | L24: SALLAGO FEDERICO MIGUEL | M24: 46287 | N24: 4500138923 | O24: 20 | P24: =_xlfn.CONCAT(N24:O24) -> 450013892320 | Q24: {=VLOOKUP(P24,Hoja1!C:F,{2,3,4},FALSE)} -> 46303 | R24: C01 | S24: 1000011519 SALLAGO FEDERICO MIGUEL | T24: =VLOOKUP(P24,Hoja2!C:D,2,FALSE) -> AZAPANA
C25: 5100001614 | E25: RE | F25: 46275 | G25: 96 | H25: -252893.68 | I25: ARS | J25: C1 | L25: SALLAGO FEDERICO MIGUEL | M25: 46287 | N25: 4500138923 | O25: 30 | P25: =_xlfn.CONCAT(N25:O25) -> 450013892330 | Q25: {=VLOOKUP(P25,Hoja1!C:F,{2,3,4},FALSE)} -> 46303 | R25: C01 | S25: 1000011519 SALLAGO FEDERICO MIGUEL | T25: =VLOOKUP(P25,Hoja2!C:D,2,FALSE) -> AZAPANA
C26: 5100001614 | E26: RE | F26: 46275 | G26: 96 | H26: -126446.84 | I26: ARS | J26: C1 | L26: SALLAGO FEDERICO MIGUEL | M26: 46287 | N26: 4500138923 | O26: 40 | P26: =_xlfn.CONCAT(N26:O26) -> 450013892340 | Q26: {=VLOOKUP(P26,Hoja1!C:F,{2,3,4},FALSE)} -> 46303 | R26: C01 | S26: 1000011519 SALLAGO FEDERICO MIGUEL | T26: =VLOOKUP(P26,Hoja2!C:D,2,FALSE) -> AZAPANA
C27: 5100001614 | E27: RE | F27: 46275 | G27: 96 | H27: -126446.84 | I27: ARS | J27: C1 | L27: SALLAGO FEDERICO MIGUEL | M27: 46287 | N27: 4500138923 | O27: 50 | P27: =_xlfn.CONCAT(N27:O27) -> 450013892350 | Q27: {=VLOOKUP(P27,Hoja1!C:F,{2,3,4},FALSE)} -> 46303 | R27: C01 | S27: 1000011519 SALLAGO FEDERICO MIGUEL | T27: =VLOOKUP(P27,Hoja2!C:D,2,FALSE) -> AZAPANA
C28: 5100001614 | E28: RE | F28: 46275 | G28: 96 | H28: -252893.68 | I28: ARS | J28: C1 | L28: SALLAGO FEDERICO MIGUEL | M28: 46287 | N28: 4500138923 | O28: 60 | P28: =_xlfn.CONCAT(N28:O28) -> 450013892360 | Q28: {=VLOOKUP(P28,Hoja1!C:F,{2,3,4},FALSE)} -> 46303 | R28: C01 | S28: 1000011519 SALLAGO FEDERICO MIGUEL | T28: =VLOOKUP(P28,Hoja2!C:D,2,FALSE) -> AZAPANA
C29: 5100001614 | E29: RE | F29: 46275 | G29: 96 | H29: -505787.36 | I29: ARS | J29: C1 | L29: SALLAGO FEDERICO MIGUEL | M29: 46287 | N29: 4500138923 | O29: 70 | P29: =_xlfn.CONCAT(N29:O29) -> 450013892370 | Q29: {=VLOOKUP(P29,Hoja1!C:F,{2,3,4},FALSE)} -> 46303 | R29: C01 | S29: 1000011519 SALLAGO FEDERICO MIGUEL | T29: =VLOOKUP(P29,Hoja2!C:D,2,FALSE) -> AZAPANA
C30: 5100001616 | D30: 7000 | E30: RE | F30: 46297 | G30: 86 | H30: 2570547.8 | I30: ARS | J30: C2 | L30: TRANSPORTE TMS S. A. S. | M30: 46304 | N30: 4500137227 | O30: 10 | P30: =_xlfn.CONCAT(N30:O30) -> 450013722710 | Q30: {=VLOOKUP(P30,Hoja1!C:F,{2,3,4},FALSE)} -> 46325 | R30: C25 | S30: 1000012097 TRANSPORTE TMS S. A. S. | T30: =VLOOKUP(P30,Hoja2!C:D,2,FALSE) -> MPITTIA
C31: 5100001637 | E31: RE | F31: 46309 | G31: 86 | H31: 57851.24 | I31: ARS | J31: C1 | L31: JUAN ANTONIO GUZMAN E HIJOS SRL | M31: 46310 | N31: 4500134628 | O31: 10 | P31: =_xlfn.CONCAT(N31:O31) -> 450013462810 | Q31: {=VLOOKUP(P31,Hoja1!C:F,{2,3,4},FALSE)} -> 46314 | R31: C01 | S31: 1000013440 JUAN ANTONIO GUZMAN E HIJOS SRL | T31: =VLOOKUP(P31,Hoja2!C:D,2,FALSE) -> AZAPANA
C32: 5000000446 | D32: 7000 | E32: WE | F32: 45937 | G32: 96 | H32: -35000 | I32: ARS | L32: BOLLINI S.A | M32: 45937 | N32: 4500109841 | O32: 10 | P32: =_xlfn.CONCAT(N32:O32) -> 450010984110 | Q32: {=VLOOKUP(P32,Hoja1!C:F,{2,3,4},FALSE)} -> 45940 | R32: C27 | S32: 1000000295 BOLLINI S.A | T32: =VLOOKUP(P32,Hoja2!C:D,2,FALSE) -> JESPARZA
C33: 5000000446 | D33: 7000 | E33: WE | F33: 45937 | G33: 96 | H33: -46280.96 | I33: ARS | L33: BOLLINI S.A | M33: 45937 | N33: 4500109841 | O33: 20 | P33: =_xlfn.CONCAT(N33:O33) -> 450010984120 | Q33: {=VLOOKUP(P33,Hoja1!C:F,{2,3,4},FALSE)} -> 45940 | R33: C27 | S33: 1000000295 BOLLINI S.A | T33: =VLOOKUP(P33,Hoja2!C:D,2,FALSE) -> JESPARZA
C34: 5000000446 | D34: 7000 | E34: WE | F34: 45937 | G34: 96 | H34: -1983.6 | I34: ARS | L34: BOLLINI S.A | M34: 45937 | N34: 4500109841 | O34: 30 | P34: =_xlfn.CONCAT(N34:O34) -> 450010984130 | Q34: {=VLOOKUP(P34,Hoja1!C:F,{2,3,4},FALSE)} -> 45940 | R34: C27 | S34: 1000000295 BOLLINI S.A | T34: =VLOOKUP(P34,Hoja2!C:D,2,FALSE) -> JESPARZA
C35: 5000000641 | E35: WE | F35: 46093 | G35: 96 | H35: -3821769.9 | I35: ARS | L35: HELING S.A. | M35: 46093 | N35: 4500114743 | O35: 40 | P35: =_xlfn.CONCAT(N35:O35) -> 450011474340 | Q35: {=VLOOKUP(P35,Hoja1!C:F,{2,3,4},FALSE)} -> 46290 | R35: CGT | S35: 1000001583 HELING S.A. | T35: =VLOOKUP(P35,Hoja2!C:D,2,FALSE) -> EFUNES
C36: 5000000641 | E36: WE | F36: 46093 | G36: 96 | H36: -2872870 | I36: ARS | L36: HELING S.A. | M36: 46093 | N36: 4500114743 | O36: 50 | P36: =_xlfn.CONCAT(N36:O36) -> 450011474350 | Q36: {=VLOOKUP(P36,Hoja1!C:F,{2,3,4},FALSE)} -> 46290 | R36: CGT | S36: 1000001583 HELING S.A. | T36: =VLOOKUP(P36,Hoja2!C:D,2,FALSE) -> EFUNES
C37: 5000000641 | E37: WE | F37: 46093 | G37: 96 | H37: -41745 | I37: ARS | L37: HELING S.A. | M37: 46093 | N37: 4500114743 | O37: 60 | P37: =_xlfn.CONCAT(N37:O37) -> 450011474360 | Q37: {=VLOOKUP(P37,Hoja1!C:F,{2,3,4},FALSE)} -> 46290 | R37: CGT | S37: 1000001583 HELING S.A. | T37: =VLOOKUP(P37,Hoja2!C:D,2,FALSE) -> EFUNES
C38: 5000000641 | E38: WE | F38: 46093 | G38: 96 | H38: -13953.5 | I38: ARS | L38: HELING S.A. | M38: 46093 | N38: 4500114743 | O38: 170 | P38: =_xlfn.CONCAT(N38:O38) -> 4500114743170 | Q38: {=VLOOKUP(P38,Hoja1!C:F,{2,3,4},FALSE)} -> 46290 | R38: CGT | S38: 1000001583 HELING S.A. | T38: =VLOOKUP(P38,Hoja2!C:D,2,FALSE) -> EFUNES
C39: 5000000641 | E39: WE | F39: 46093 | G39: 96 | H39: -114141.5 | I39: ARS | L39: HELING S.A. | M39: 46093 | N39: 4500114743 | O39: 320 | P39: =_xlfn.CONCAT(N39:O39) -> 4500114743320 | Q39: {=VLOOKUP(P39,Hoja1!C:F,{2,3,4},FALSE)} -> 46290 | R39: CGT | S39: 1000001583 HELING S.A. | T39: =VLOOKUP(P39,Hoja2!C:D,2,FALSE) -> EFUNES
C40: 5000000684 | D40: 7000 | E40: WE | F40: 46100 | G40: 96 | H40: -59456.97 | I40: ARS | L40: JACARANDA S.A. | M40: 46100 | N40: 4500109514 | O40: 10 | P40: =_xlfn.CONCAT(N40:O40) -> 450010951410 | Q40: {=VLOOKUP(P40,Hoja1!C:F,{2,3,4},FALSE)} -> 46162 | R40: C01 | S40: 1000008967 JACARANDA S.A. | T40: =VLOOKUP(P40,Hoja2!C:D,2,FALSE) -> MMOHR
...

Sheet Hoja2
A1: NRO. OC | B1: POS. OC | D1: OPERADOR OC
A2: 4500109514 | B2: 10 | C2: =_xlfn.CONCAT(A2:B2) -> 450010951410 | D2: MMOHR
A3: 4500109841 | B3: 10 | C3: =_xlfn.CONCAT(A3:B3) -> 450010984110 | D3: JESPARZA
A4: 4500109841 | B4: 20 | C4: =_xlfn.CONCAT(A4:B4) -> 450010984120 | D4: JESPARZA
A5: 4500109841 | B5: 30 | C5: =_xlfn.CONCAT(A5:B5) -> 450010984130 | D5: JESPARZA
A6: 4500110226 | B6: 20 | C6: =_xlfn.CONCAT(A6:B6) -> 450011022620 | D6: EFUNES
A7: 4500109709 | B7: 10 | C7: =_xlfn.CONCAT(A7:B7) -> 450010970910 | D7: MPITTIA
A8: 4500112079 | B8: 30 | C8: =_xlfn.CONCAT(A8:B8) -> 450011207930 | D8: GJULIANI
A9: 4500112079 | B9: 20 | C9: =_xlfn.CONCAT(A9:B9) -> 450011207920 | D9: GJULIANI
A10: 4500113920 | B10: 10 | C10: =_xlfn.CONCAT(A10:B10) -> 450011392010 | D10: MPITTIA
A11: 4500113800 | B11: 10 | C11: =_xlfn.CONCAT(A11:B11) -> 450011380010 | D11: MMOHR
A12: 4500113800 | B12: 20 | C12: =_xlfn.CONCAT(A12:B12) -> 450011380020 | D12: MMOHR
A13: 4500113800 | B13: 30 | C13: =_xlfn.CONCAT(A13:B13) -> 450011380030 | D13: MMOHR
... A460: 4500141005 | B460: 10 | C460: =_xlfn.CONCAT(A460:B460) -> 450014100510 | D460: AZAPANA

Sheet Hoja1
A1: Documento compras | B1: Posición | D1: Fecha de entrega | E1: Grupo de compras | F1: Proveedor/Centro suministrador
A2: 4500114168 | B2: 30 | C2: =_xlfn.CONCAT(A2:B2) -> 450011416830 | D2: 46387 | E2: C15 | F2: 1000000069 V.MASSON TRAP.CRUZ DEL SUR SA
A3: 4500120184 | B3: 10 | C3: =_xlfn.CONCAT(A3:B3) -> 450012018410 | D3: 46321 | E3: C15 | F3: 1000000104 TRANSPORTES LA SEVILLANITA SRL
A4: 4500114168 | B4: 40 | C4: =_xlfn.CONCAT(A4:B4) -> 450011416840 | D4: 46387 | E4: C15 | F4: 1000000069 V.MASSON TRAP.CRUZ DEL SUR SA
A5: 4500139298 | B5: 10 | C5: =_xlfn.CONCAT(A5:B5) -> 450013929810 | D5: 46325 | E5: C25 | F5: 1000012097 TRANSPORTE TMS S. A. S.
A6: 4500109709 | B6: 10 | C6: =_xlfn.CONCAT(A6:B6) -> 450010970910 | D6: 46308 | E6: C25 | F6: 1000007510 LABTEC S. R. L.
A7: 4500134256 | B7: 10 | C7: =_xlfn.CONCAT(A7:B7) -> 450013425610 | D7: 46322 | E7: C01 | F7: 1000008967 JACARANDA S.A.
A8: 4500113920 | B8: 10 | C8: =_xlfn.CONCAT(A8:B8) -> 450011392010 | D8: 46325 | E8: C25 | F8: 1000012293 ZAMBRANA SAMUEL
A9: 4500134824 | B9: 10 | C9: =_xlfn.CONCAT(A9:B9) -> 450013482410 | D9: 46325 | E9: C25 | F9: 1000012132 PRODUCTOS SERVICIOS Y DISTRIBUCIONE
A10: 4500114743 | B10: 390 | C10: =_xlfn.CONCAT(A10:B10) -> 4500114743390 | D10: 46301 | E10: CGT | F10: 1000001583 HELING S.A.
A11: 4500128533 | B11: 20 | C11: =_xlfn.CONCAT(A11:B11) -> 450012853320 | D11: 46326 | E11: C25 | F11: 1000012132 PRODUCTOS SERVICIOS Y DISTRIBUCIONE
A12: 4500139298 | B12: 20 | C12: =_xlfn.CONCAT(A12:B12) -> 450013929820 | D12: 46325 | E12: C25 | F12: 1000012097 TRANSPORTE TMS S. A. S.
A13: 4500137422 | B13: 40 | C13: =_xlfn.CONCAT(A13:B13) -> 450013742240 | D13: 46328 | E13: C24 | F13: 1000012877 RASGIDO GASTON ANDRES
... A460: 4500141064 | B460: 10 | C460: =_xlfn.CONCAT(A460:B460) -> 450014106410 | D460: 46310 | E460: C01 | F460: 1000000566 AUTOLUX SA
